Workbook

Sheet JLOS_data
A1: X-Y SCALE>> | B1: =100/Inputs!B30 -> 1.3333333 | C1: =50/Inputs!B31 -> 12.5 | F1: OVERALL LOS >> | G1: =Inputs!F33 -> 53
A2: 1 | B2: =Inputs!F$2*$B$1 -> 13.333333 | C2: =Inputs!F$3*$C$1 -> -6.25 | D2: =Inputs!F$4 -> 2 | E2: =Inputs!F$7 -> 1 | F2: =Inputs!F$8 -> 0 | G2: =Inputs!F$5 -> 54
A3: 2 | B3: =Inputs!G$2*$B$1 -> 61.333333 | C3: =Inputs!G$3*$C$1 -> 0 | D3: =Inputs!G$4 -> 1 | E3: =Inputs!G$7 -> 0 | F3: =Inputs!G$8 -> 0 | G3: =Inputs!G$5 -> 52
A4: 3 | B4: =Inputs!H$2*$B$1 -> 306.66667 | C4: =Inputs!H$3*$C$1 -> 0 | D4: =Inputs!H$4 -> 1 | E4: =Inputs!H$7 -> 2 | F4: =Inputs!H$8 -> 18 | G4: =Inputs!H$5 -> 54
A5: 4 | B5: =Inputs!I$2*$B$1 -> 194.66667 | C5: =Inputs!I$3*$C$1 -> 0 | D5: =Inputs!I$4 -> 1 | E5: =Inputs!I$7 -> 0 | F5: =Inputs!I$8 -> 0 | G5: =Inputs!I$5 -> 52
A6: 5 | B6: =Inputs!J$2*$B$1 -> 26.666667 | C6: =Inputs!J$3*$C$1 -> 162.5 | D6: =Inputs!J$4 -> 2 | E6: =Inputs!J$7 -> 0 | F6: =Inputs!J$8 -> 16 | G6: =Inputs!J$5 -> 55
A7: 6 | B7: =Inputs!K$2*$B$1 -> 50.666667 | C7: =Inputs!K$3*$C$1 -> 0 | D7: =Inputs!K$4 -> 2 | E7: =Inputs!K$7 -> 0 | F7: =Inputs!K$8 -> 0 | G7: =Inputs!K$5 -> 52
A8: 7 | B8: =Inputs!L$2*$B$1 -> 122.66667 | C8: =Inputs!L$3*$C$1 -> -162.5 | D8: =Inputs!L$4 -> 2 | E8: =Inputs!L$7 -> 0 | F8: =Inputs!L$8 -> 0 | G8: =Inputs!L$5 -> 53
A9: 8 | B9: =Inputs!M$2*$B$1 -> 13.333333 | C9: =Inputs!M$3*$C$1 -> 0 | D9: =Inputs!M$4 -> 1 | E9: =Inputs!M$7 -> 0 | F9: =Inputs!M$8 -> 0 | G9: =Inputs!M$5 -> 52
A10: 9 | B10: =Inputs!N$2*$B$1 -> 0 | C10: =Inputs!N$3*$C$1 -> 0 | D10: =Inputs!N$4 -> 0 | E10: =Inputs!N$7 -> 0 | F10: =Inputs!N$8 -> 0 | G10: =Inputs!N$5 -> 0
A11: 10 | B11: =Inputs!O$2*$B$1 -> 0 | C11: =Inputs!O$3*$C$1 -> 0 | D11: =Inputs!O$4 -> 0 | E11: =Inputs!O$7 -> 0 | F11: =Inputs!O$8 -> 0 | G11: =Inputs!O$5 -> 0
A12: 11 | B12: =Inputs!P$2*$B$1 -> 0 | C12: =Inputs!P$3*$C$1 -> 0 | D12: =Inputs!P$4 -> 0 | E12: =Inputs!P$7 -> 0 | F12: =Inputs!KI$18 -> 0 | G12: =Inputs!P$5 -> 0
A13: 12 | B13: =Inputs!Q$2*$B$1 -> 0 | C13: =Inputs!Q$3*$C$1 -> 0 | D13: =Inputs!LI$13 -> 0 | E13: =Inputs!Q$7 -> 0 | F13: =Inputs!Q$8 -> 0 | G13: =Inputs!Q$5 -> 0
A14: 13 | B14: =Inputs!R$2*$B$1 -> 0 | C14: =Inputs!R$3*$C$1 -> 0 | D14: =Inputs!R$4 -> 0 | E14: =Inputs!R$7 -> 0 | F14: =Inputs!R$8 -> 0 | G14: =Inputs!R$5 -> 0
A15: 14 | B15: =Inputs!S$2*$B$1 -> 0 | C15: =Inputs!S$3*$C$1 -> 0 | D15: =Inputs!S$4 -> 0 | E15: =Inputs!S$7 -> 0 | F15: =Inputs!S$8 -> 0 | G15: =Inputs!S$5 -> 0
A16: 15 | B16: =Inputs!T$2*$B$1 -> 0 | C16: =Inputs!T$3*$C$1 -> 0 | D16: =Inputs!T$4 -> 0 | E16: =Inputs!T$7 -> 0 | F16: =Inputs!T$8 -> 0 | G16: =Inputs!T$5 -> 0
A17: 16 | B17: =Inputs!U$2*$B$1 -> 0 | C17: =Inputs!U$3*$C$1 -> 0 | D17: =Inputs!U$4 -> 0 | E17: =Inputs!U$7 -> 0 | F17: =Inputs!U$8 -> 0 | G17: =Inputs!U$5 -> 0
A18: 17 | B18: =Inputs!V$2*$B$1 -> 0 | C18: =Inputs!V$3*$C$1 -> 0 | D18: =Inputs!V$4 -> 0 | E18: =Inputs!V$7 -> 0 | F18: =Inputs!V$8 -> 0 | G18: =Inputs!V$5 -> 0
A19: 18 | B19: =Inputs!W$2*$B$1 -> 0 | C19: =Inputs!W$3*$C$1 -> 0 | D19: =Inputs!W$4 -> 0 | E19: =Inputs!W$7 -> 0 | F19: =Inputs!W$8 -> 0 | G19: =Inputs!RI$42 -> 0
A20: 19 | B20: =Inputs!X$2*$B$1 -> 0 | C20: =Inputs!X$3*$C$1 -> 0 | D20: =Inputs!X$4 -> 0 | E20: =Inputs!X$7 -> 0 | F20: =Inputs!X$8 -> 0 | G20: =Inputs!X$5 -> 0
A21: 20 | B21: =Inputs!Y$2*$B$1 -> 0 | C21: =Inputs!Y$3*$C$1 -> 0 | D21: =Inputs!Y$4 -> 0 | E21: =Inputs!Y$7 -> 0 | F21: =Inputs!Y$8 -> 0 | G21: =Inputs!Y$5 -> 0
A22: 21 | B22: =Inputs!Z$2*$B$1 -> 0 | C22: =Inputs!Z$3*$C$1 -> 0 | D22: =Inputs!Z$4 -> 0 | E22: =Inputs!Z$7 -> 0 | F22: =Inputs!Z$8 -> 0 | G22: =Inputs!Z$5 -> 0
A23: 22 | B23: =Inputs!AA$2*$B$1 -> 0 | C23: =Inputs!AA$3*$C$1 -> 0 | D23: =Inputs!AA$4 -> 0 | E23: =Inputs!AA$7 -> 0 | F23: =Inputs!AA$8 -> 0 | G23: =Inputs!AA$5 -> 0
A24: 23 | B24: =Inputs!AB$2*$B$1 -> 0 | C24: =Inputs!AB$3*$C$1 -> 0 | D24: =Inputs!AB$4 -> 0 | E24: =Inputs!AB$7 -> 0 | F24: =Inputs!WI$18 -> 0 | G24: =Inputs!AB$5 -> 0
A25: 24 | B25: =Inputs!AC$2*$B$1 -> 0 | C25: =Inputs!AC$3*$C$1 -> 0 | D25: =Inputs!AC$4 -> 0 | E25: =Inputs!AC$7 -> 0 | F25: =Inputs!XI$18 -> 0 | G25: =Inputs!AC$5 -> 0
A26: 25 | B26: =Inputs!AD$2*$B$1 -> 0 | C26: =Inputs!AD$3*$C$1 -> 0 | D26: =Inputs!YI$13 -> 0 | E26: =Inputs!AD$7 -> 0 | F26: =Inputs!AD$8 -> 0 | G26: =Inputs!AD$5 -> 0
A27: 26 | B27: =Inputs!AE$2*$B$1 -> 0 | C27: =Inputs!AE$3*$C$1 -> 0 | D27: =Inputs!AE$4 -> 0 | E27: =Inputs!AE$7 -> 0 | F27: =Inputs!AE$8 -> 0 | G27: =Inputs!AE$5 -> 0
A28: 27 | B28: =Inputs!AF$2*$B$1 -> 0 | C28: =Inputs!AF$3*$C$1 -> 0 | D28: =Inputs!AF$4 -> 0 | E28: =Inputs!AF$7 -> 0 | F28: =Inputs!AF$8 -> 0 | G28: =Inputs!AF$5 -> 0
A29: 28 | B29: =Inputs!AG$2*$B$1 -> 0 | C29: =Inputs!AG$3*$C$1 -> 0 | D29: =Inputs!D$4 -> 0 | E29: =Inputs!AG$7 -> 0 | F29: =Inputs!AG$8 -> 0 | G29: =Inputs!AG$5 -> 0
A30: 29 | B30: =Inputs!AH$2*$B$1 -> 0 | C30: =Inputs!ACI$12*$C$1 -> 0 | D30: =Inputs!AH$4 -> 0 | E30: =Inputs!AH$7 -> 0 | F30: =Inputs!AH$8 -> 0 | G30: =Inputs!AH$5 -> 0
A31: TOTAL>> | B31: =SUM(B2:B30)/B1 -> 592 | C31: =SUM(C2:C30)/C1 -> -0.5
A32: =IF(Inputs!A9="","",Inputs!A9) -> GF | B32: =IF(Inputs!A8="","",Inputs!A8) -> L1 | C32: =IF(Inputs!A7="","",Inputs!A7) | D32: =IF(Inputs!A6="","",Inputs!A6) | E32: =IF(Inputs!A5="","",Inputs!A5) | F32: =IF(Inputs!A4="","",Inputs!A4) | G32: =IF(Inputs!A3="","",Inputs!A3) | H32: =IF(Inputs!A2="","",Inputs!A2)
A33: =Inputs!B9 -> 0.5 | B33: =Inputs!B8 -> 13 | C33: =Inputs!B7 -> 0 | D33: =Inputs!B6 -> 0 | E33: =Inputs!B5 -> 0 | F33: =Inputs!B4 -> 0 | G33: =Inputs!B3 -> 0 | H33: =Inputs!B2 -> 0

Sheet Inputs
A1: Level | B1: (m) | E1: SEGMENT DATA | F1: 01 | G1: 02 | H1: 03 | I1: 04 | J1: 05 | K1: 06 | L1: 07 | M1: 08 | N1: 09 | O1: 10 | P1: 11 | Q1: 12 | R1: 13 | S1: 14 | T1: 15 | U1: 16 | V1: 17 | W1: 18 | X1: 19 | Y1: 20 | Z1: 21 | AA1: 22 | AB1: 23 | AC1: 24 | AD1: 25 | AE1: 26 | AF1: 27 | AG1: 28 | AH1: 29
E2: Horizontal Distance (m) | F2: 10 | G2: 46 | H2: 230 | I2: 146 | J2: 20 | K2: 38 | L2: 92 | M2: 10
E3: Vertical Distance (m) | F3: -0.5 | G3: 0 | H3: 0 | I3: 0 | J3: 13 | K3: 0 | L3: -13 | M3: 0
E4: Weather Protection (1=Open-air | 2=Sheltered | 3=Air-conditioned) | F4: 2 | G4: 1 | H4: 1 | I4: 1 | J4: 2 | K4: 2 | L4: 2 | M4: 1
E5: Level of Service (A=50 | B=51 | C=52 | D=53 | E=54 | F=55) | F5: 54 | G5: 52 | H5: 54 | I5: 52 | J5: 55 | K5: 52 | L5: 53 | M5: 52
E6: SEGMENT PICTO
E7: STARTING POINT of the Segment (See legend below) | F7: 1 | H7: 2
A8: L1 | B8: 13 | E8: MIDPOINT of the Segment (See legend below) | H8: 18 | J8: 16
A9: GF | B9: 0.5 | D9: 1 | E9: Metro
D10: 2 | E10: Bus
D11: 3 | E11: BRT
D12: 4 | E12: Tour Coach
D13: 5 | E13: Rail
D14: 6 | E14: Air Taxi
D15: 7 | E15: Minibus
D16: 8 | E16: Ferry
D17: 9 | E17: Taxi
D18: 10 | E18: Uber
D19: 11 | E19: Bike
D20: 12 | E20: Private Car
D21: 13 | E21: Autonomous Vehicle
... D28: 20 | E28: Toilet
A29: Grid | B29: (m) | D29: 21 | E29: Retail
A30: X | B30: 75 | D30: 22 | E30: Ticketing
A31: Y | B31: 4 | D31: 23 | E31: Food & Beverages
E32: OVERALL JLOS
E33: Level of Service (A=50 | B=51 | C=52 | D=53 | E=54 | F=55) | F33: 53
L40: 2.5 | M40: 2

Sheet HIDDEN - Assumptions
A1: PLANNING ASSUMPTIONS | B1: UNIT
A2: Walking Speed | B2: m/min | C2: 50
A3: Escalator Speed | B3: m/min | C3: 36
A4: Escalator Nominal Capacity | B4: pax/min | C4: 100
A5: Effective Width Reduction (both sides) | B5: m | C5: =2*18*2.54/100 -> 0.9144
A6: Peak Hour Factor (Hour to 5-min) | B6: % | C6: 0.15
A8: FRUIN LOS: GRADIENT < 8.3% | B8: PFM | C8: LOS
B9: 0 | C9: A
B10: 7 | C10: B
B11: 10 | C11: C
B12: 15 | C12: D
B13: 20 | C13: E
B14: 25 | C14: F
A16: FRUIN LOS: STAIR | B16: PFM | C16: LOS
B17: 0 | C17: A
B18: 5 | C18: B
B19: 7 | C19: C
B20: 10 | C20: D
B21: 13 | C21: E
B22: 17 | C22: F

Sheet HIDDEN - vlookup
A1: metro | B1: 1
A2: bus | B2: 2
A3: BRT | B3: 3
A4: tour coach | B4: 4
A5: rail | B5: 5
A6: air arrival | B6: 6
A7: air departure | B7: 7
A8: ferry | B8: 8
A9: taxi | B9: 9
A10: uber | B10: 10
A11: bike | B11: 11
A12: private car | B12: 12
... A15: cable car | B15: 15
B16: 16
B17: 17
B18: 18
B19: 19
B20: 20
A21: escalator up | B21: 21
A22: escalator down | B22: 22
A23: stair up | B23: 23
A24: stair down | B24: 24
A25: counterflow | B25: 25
A26: crossflow | B26: 26
A27: counterflow and crossflow | B27: 27
A28: bottleneck | B28: 28
A29: turnstiles | B29: 29
A30: queuing | B30: 30
A31: wc | B31: 31
A32: retail | B32: 32
... A35: switch back | B35: 35
B36: 36
B37: 37
B38: 38
B39: 39
B40: 40
B41: 41
B42: 42
B43: 43
B44: 44
...

Sheet HIDDEN - LOS Calculation
A1: SEGMENT | B1: XXXXXXXXX | C1: XXX | D1: 00 | E1: 01
A2: Passenger Flow Rate
A3: Peak Hour | B3: m/min | C3: u | E3: 1000
A4: Peak 5-min | B4: m/min | E4: =E3*'HIDDEN - Assumptions'!C6 -> 150
A5: Distance Traveled
A6: Horizton al Distance | B6: m | C6: u | E6: 7
A7: Vertical Distance | B7: m | C7: u | E7: 5
A8: Environment
A9: Open-air? | B9: OA | C9: u
A10: Sheltered? | B10: SH | C10: u
A11: Air-conditioned? | B11: AC | C11: u
A12: Activity
A13: Start | C13: u
A14: Middle | C14: u
A15: Assistance
A16: Ramp? | B16: RA | C16: u
A17: Stair? | B17: ST | C17: u
A18: Escalator? | B18: ES | C18: u
A19: Elevator? | B19: EL | C19: u
A20: Resistance
A21: Crossflow? | B21: CR | C21: u
A22: Counterflow? | B22: CO | C22: u
A27: Fruin LOS Score
A28: Case 1: Gradient < 8.3% (1 in 12)
A29: Corridor Width (Gross) | C29: u | E29: 11
A30: Corridor Width (Effective) | E30: =E29-'HIDDEN - Assumptions'!$C$5 -> 10.0856
A31: PFM | E31: =$E$4/($E$30*3.3) -> 4.5068757
A32: Fruin LOS Score | E32: =VLOOKUP(E31,'HIDDEN - Assumptions'!B8:C14,2,TRUE) -> A
A33: Case 2: Stair
A34: Corridor Width (Gross) | C34: u | E34: 11
A35: Corridor Width (Effective) | E35: =E34-'HIDDEN - Assumptions'!$C$5 -> 10.0856
A36: PFM | E36: =$E$4/($E$35*3.3) -> 4.5068757
A37: Fruin LOS Score | E37: =VLOOKUP(E36,'HIDDEN - Assumptions'!B16:C22,2,TRUE) -> A
A38: Case 3: Escalator Only
A39: No. of Escalators | C39: u | E39: 3
A40: Redundancy | B40: Y/N | C40: u | E40: Y
A41: Escalator Capacity | B41: pax/min | E41: =E39*'HIDDEN - Assumptions'!$C$4*5 -> 1500
A42: Fruin LOS Score | E42: =IF(E4>E41,"F","A") -> A
A43: Case 4: Escalator+Stair
A44: No. of Escalators | C44: u | E44: 2
...
